Traceback (most recent call last):
  File "/usr/local/lib/python3.7/dist-packages/jupyter_cache/executors/utils.py", line 56, in single_nb_execution
    record_timing=False,
  File "/usr/local/lib/python3.7/dist-packages/nbclient/client.py", line 1107, in execute
    return NotebookClient(nb=nb, resources=resources, km=km, **kwargs).execute()
  File "/usr/local/lib/python3.7/dist-packages/nbclient/util.py", line 74, in wrapped
    return just_run(coro(*args, **kwargs))
  File "/usr/local/lib/python3.7/dist-packages/nbclient/util.py", line 53, in just_run
    return loop.run_until_complete(coro)
  File "/usr/lib/python3.7/asyncio/base_events.py", line 587, in run_until_complete
    return future.result()
  File "/usr/local/lib/python3.7/dist-packages/nbclient/client.py", line 554, in async_execute
    cell, index, execution_count=self.code_cells_executed + 1
  File "/usr/local/lib/python3.7/dist-packages/nbclient/client.py", line 852, in async_execute_cell
    self._check_raise_for_error(cell, exec_reply)
  File "/usr/local/lib/python3.7/dist-packages/nbclient/client.py", line 760, in _check_raise_for_error
    raise CellExecutionError.from_cell_and_msg(cell, exec_reply_content)
nbclient.exceptions.CellExecutionError: An error occurred while executing the following cell:
------------------
X = GPU_data(X)
X_test = GPU_data(X_test)

# Y = GPU_data(Y)
# Y_test = GPU_data(Y_test)
------------------

[0;31m[0m
[0;31mRuntimeError[0mTraceback (most recent call last)
[0;32m<ipython-input-15-5af949c5d5db>[0m in [0;36m<module>[0;34m()[0m
[0;32m----> 1[0;31m [0mX[0m [0;34m=[0m [0mGPU_data[0m[0;34m([0m[0mX[0m[0;34m)[0m[0;34m[0m[0;34m[0m[0m
[0m[1;32m      2[0m [0mX_test[0m [0;34m=[0m [0mGPU_data[0m[0;34m([0m[0mX_test[0m[0;34m)[0m[0;34m[0m[0;34m[0m[0m
[1;32m      3[0m [0;34m[0m[0m
[1;32m      4[0m [0;31m# Y = GPU_data(Y)[0m[0;34m[0m[0;34m[0m[0;34m[0m[0m
[1;32m      5[0m [0;31m# Y_test = GPU_data(Y_test)[0m[0;34m[0m[0;34m[0m[0;34m[0m[0m

[0;32m<ipython-input-6-c3d856de2607>[0m in [0;36mGPU_data[0;34m(data)[0m
[1;32m      3[0m [0;34m[0m[0m
[1;32m      4[0m [0;32mdef[0m [0mGPU_data[0m[0;34m([0m[0mdata[0m[0;34m)[0m[0;34m:[0m[0;34m[0m[0;34m[0m[0m
[0;32m----> 5[0;31m     [0;32mreturn[0m [0mtorch[0m[0;34m.[0m[0mtensor[0m[0;34m([0m[0mdata[0m[0;34m,[0m [0mrequires_grad[0m[0;34m=[0m[0;32mFalse[0m[0;34m,[0m [0mdtype[0m[0;34m=[0m[0mtorch[0m[0;34m.[0m[0mfloat[0m[0;34m,[0m [0mdevice[0m[0;34m=[0m[0mtorch[0m[0;34m.[0m[0mdevice[0m[0;34m([0m[0;34m'cuda'[0m[0;34m)[0m[0;34m)[0m[0;34m[0m[0;34m[0m[0m
[0m
[0;32m/usr/local/lib/python3.7/dist-packages/torch/cuda/__init__.py[0m in [0;36m_lazy_init[0;34m()[0m
[1;32m    170[0m         [0;31m# This function throws if there's a driver initialization error, no GPUs[0m[0;34m[0m[0;34m[0m[0;34m[0m[0m
[1;32m    171[0m         [0;31m# are found or any other error occurs[0m[0;34m[0m[0;34m[0m[0;34m[0m[0m
[0;32m--> 172[0;31m         [0mtorch[0m[0;34m.[0m[0m_C[0m[0;34m.[0m[0m_cuda_init[0m[0;34m([0m[0;34m)[0m[0;34m[0m[0;34m[0m[0m
[0m[1;32m    173[0m         [0;31m# Some of the queued calls may reentrantly call _lazy_init();[0m[0;34m[0m[0;34m[0m[0;34m[0m[0m
[1;32m    174[0m         [0;31m# we need to just return without initializing in that case.[0m[0;34m[0m[0;34m[0m[0;34m[0m[0m

[0;31mRuntimeError[0m: No CUDA GPUs are available
RuntimeError: No CUDA GPUs are available

